[2025-04-02T12:50:43.927+0000] {taskinstance.py:1159} INFO - Dependencies all met for dep_context=non-requeueable deps ti=<TaskInstance: fetch_transaction_data_and_upload_to_hdfs.upload_to_hdfs scheduled__2025-04-01T00:00:00+00:00 [queued]>
[2025-04-02T12:50:43.941+0000] {taskinstance.py:1159} INFO - Dependencies all met for dep_context=requeueable deps ti=<TaskInstance: fetch_transaction_data_and_upload_to_hdfs.upload_to_hdfs scheduled__2025-04-01T00:00:00+00:00 [queued]>
[2025-04-02T12:50:43.942+0000] {taskinstance.py:1361} INFO - Starting attempt 1 of 2
[2025-04-02T12:50:43.962+0000] {taskinstance.py:1382} INFO - Executing <Task(PythonOperator): upload_to_hdfs> on 2025-04-01 00:00:00+00:00
[2025-04-02T12:50:43.969+0000] {standard_task_runner.py:57} INFO - Started process 186 to run task
[2025-04-02T12:50:43.974+0000] {standard_task_runner.py:84} INFO - Running: ['***', 'tasks', 'run', 'fetch_transaction_data_and_upload_to_hdfs', 'upload_to_hdfs', 'scheduled__2025-04-01T00:00:00+00:00', '--job-id', '10', '--raw', '--subdir', 'DAGS_FOLDER/ingestion.py', '--cfg-path', '/tmp/tmpzq5s2wlh']
[2025-04-02T12:50:43.978+0000] {standard_task_runner.py:85} INFO - Job 10: Subtask upload_to_hdfs
[2025-04-02T12:50:44.038+0000] {task_command.py:415} INFO - Running <TaskInstance: fetch_transaction_data_and_upload_to_hdfs.upload_to_hdfs scheduled__2025-04-01T00:00:00+00:00 [running]> on host a196b81e404f
[2025-04-02T12:50:44.143+0000] {taskinstance.py:1660} INFO - Exporting env vars: AIRFLOW_CTX_DAG_OWNER='***' AIRFLOW_CTX_DAG_ID='fetch_transaction_data_and_upload_to_hdfs' AIRFLOW_CTX_TASK_ID='upload_to_hdfs' AIRFLOW_CTX_EXECUTION_DATE='2025-04-01T00:00:00+00:00' AIRFLOW_CTX_TRY_NUMBER='1' AIRFLOW_CTX_DAG_RUN_ID='scheduled__2025-04-01T00:00:00+00:00'
[2025-04-02T12:50:46.545+0000] {taskinstance.py:1943} ERROR - Task failed with exception
Traceback (most recent call last):
  File "/home/airflow/.local/lib/python3.9/site-packages/airflow/operators/python.py", line 192, in execute
    return_value = self.execute_callable()
  File "/home/airflow/.local/lib/python3.9/site-packages/airflow/operators/python.py", line 209, in execute_callable
    return self.python_callable(*self.op_args, **self.op_kwargs)
  File "/opt/airflow/dags/ingestion.py", line 50, in upload_to_hdfs
    raise Exception(f"Command failed: {bash_command}\nError: {result.stderr}")
Exception: Command failed: docker cp /tmp/transaction_data.csv namenode:/tmp/transaction_data.csv &&docker exec namenode bash -c "hdfs dfs -mkdir -p /user/root/transactions/YYYY=2025/MM=04/DD=01 && hdfs dfs -put -f /tmp/transaction_data.csv /user/root/transactions/YYYY=2025/MM=04/DD=01/transaction_data.csv"
Error: mkdir: Cannot create directory /user/root/transactions/YYYY=2025/MM=04/DD=01. Name node is in safe mode.

[2025-04-02T12:50:46.559+0000] {taskinstance.py:1400} INFO - Marking task as UP_FOR_RETRY. dag_id=fetch_transaction_data_and_upload_to_hdfs, task_id=upload_to_hdfs, execution_date=20250401T000000, start_date=20250402T125043, end_date=20250402T125046
[2025-04-02T12:50:46.577+0000] {standard_task_runner.py:104} ERROR - Failed to execute job 10 for task upload_to_hdfs (Command failed: docker cp /tmp/transaction_data.csv namenode:/tmp/transaction_data.csv &&docker exec namenode bash -c "hdfs dfs -mkdir -p /user/root/transactions/YYYY=2025/MM=04/DD=01 && hdfs dfs -put -f /tmp/transaction_data.csv /user/root/transactions/YYYY=2025/MM=04/DD=01/transaction_data.csv"
Error: mkdir: Cannot create directory /user/root/transactions/YYYY=2025/MM=04/DD=01. Name node is in safe mode.
; 186)
[2025-04-02T12:50:46.615+0000] {local_task_job_runner.py:228} INFO - Task exited with return code 1
[2025-04-02T12:50:46.641+0000] {taskinstance.py:2784} INFO - 0 downstream tasks scheduled from follow-on schedule check
