[2025-05-23T09:28:21.936+0000] {taskinstance.py:1159} INFO - Dependencies all met for dep_context=non-requeueable deps ti=<TaskInstance: fetch_transaction_data_and_upload_to_hdfs.run_superset_dashboard manual__2025-05-23T09:21:40.288251+00:00 [queued]>
[2025-05-23T09:28:21.953+0000] {taskinstance.py:1159} INFO - Dependencies all met for dep_context=requeueable deps ti=<TaskInstance: fetch_transaction_data_and_upload_to_hdfs.run_superset_dashboard manual__2025-05-23T09:21:40.288251+00:00 [queued]>
[2025-05-23T09:28:21.953+0000] {taskinstance.py:1361} INFO - Starting attempt 2 of 2
[2025-05-23T09:28:21.975+0000] {taskinstance.py:1382} INFO - Executing <Task(BashOperator): run_superset_dashboard> on 2025-05-23 09:21:40.288251+00:00
[2025-05-23T09:28:21.987+0000] {standard_task_runner.py:57} INFO - Started process 688 to run task
[2025-05-23T09:28:21.993+0000] {standard_task_runner.py:84} INFO - Running: ['***', 'tasks', 'run', 'fetch_transaction_data_and_upload_to_hdfs', 'run_superset_dashboard', 'manual__2025-05-23T09:21:40.288251+00:00', '--job-id', '23', '--raw', '--subdir', 'DAGS_FOLDER/ETL.py', '--cfg-path', '/tmp/tmphw3zlx3a']
[2025-05-23T09:28:21.997+0000] {standard_task_runner.py:85} INFO - Job 23: Subtask run_superset_dashboard
[2025-05-23T09:28:22.106+0000] {task_command.py:415} INFO - Running <TaskInstance: fetch_transaction_data_and_upload_to_hdfs.run_superset_dashboard manual__2025-05-23T09:21:40.288251+00:00 [running]> on host 6c702459c558
[2025-05-23T09:28:22.550+0000] {taskinstance.py:1660} INFO - Exporting env vars: AIRFLOW_CTX_DAG_OWNER='***' AIRFLOW_CTX_DAG_ID='fetch_transaction_data_and_upload_to_hdfs' AIRFLOW_CTX_TASK_ID='run_superset_dashboard' AIRFLOW_CTX_EXECUTION_DATE='2025-05-23T09:21:40.288251+00:00' AIRFLOW_CTX_TRY_NUMBER='2' AIRFLOW_CTX_DAG_RUN_ID='manual__2025-05-23T09:21:40.288251+00:00'
[2025-05-23T09:28:22.553+0000] {subprocess.py:63} INFO - Tmp dir root location: /tmp
[2025-05-23T09:28:22.555+0000] {subprocess.py:75} INFO - Running command: ['/bin/bash', '-c', 'docker exec superset python /app/dashboard/step1_connection_db.py && docker exec superset python /app/dashboard/step2_creation_of_datasets.py && docker exec superset python /app/dashboard/step3_create_charts.py && docker exec superset python step4_create_dashbord.py']
[2025-05-23T09:28:22.580+0000] {subprocess.py:86} INFO - Output:
[2025-05-23T09:28:43.524+0000] {subprocess.py:93} INFO - ‚úÖ Login successful.
[2025-05-23T09:28:43.526+0000] {subprocess.py:93} INFO - Access Token: eyJhbGciOiJIUzI1NiIsInR5cCI6IkpXVCJ9.eyJmcmVzaCI6dHJ1ZSwiaWF0IjoxNzQ3OTkyNTA4LCJqdGkiOiIyZjVlOWM0ZC0yNjc1LTQ5YjItYTJjZC0yNjM5MmYzMmNiMWYiLCJ0eXBlIjoiYWNjZXNzIiwic3ViIjoxLCJuYmYiOjE3NDc5OTI1MDgsImNzcmYiOiI1N2NmZjQwMC1jMTVhLTRmYWEtOTkyOS04MzY3YWEyMjUzMWIiLCJleHAiOjE3NDc5OTM0MDh9.OwmPlQN_vqfcELe4lrL2XaBWr6SwIxcayllKN4eyNsg
[2025-05-23T09:28:43.527+0000] {subprocess.py:93} INFO - ‚úÖ CSRF token received:
[2025-05-23T09:28:43.527+0000] {subprocess.py:93} INFO - IjdjMzExNzRkNTRjMjZjNjA0ZjBkOWNjNjlkYWQ4ZDI1NWYxOWVhM2Qi.aDA_vA.yHRfx43i8LgPGOc0zrV7SNWsIew
[2025-05-23T09:28:43.528+0000] {subprocess.py:93} INFO - Status: 422
[2025-05-23T09:28:43.528+0000] {subprocess.py:93} INFO - Response: {"message":{"database_name":"A database with the same name already exists."}}
[2025-05-23T09:28:43.529+0000] {subprocess.py:93} INFO - 
[2025-05-23T09:29:21.372+0000] {subprocess.py:93} INFO - ‚úÖ Logged in successfully
[2025-05-23T09:29:21.374+0000] {subprocess.py:93} INFO - ‚úÖ CSRF token retrieved
[2025-05-23T09:29:21.375+0000] {subprocess.py:93} INFO - ‚úÖ Hive Warehouse database ID: 1
[2025-05-23T09:29:21.376+0000] {subprocess.py:93} INFO - ‚ùå Failed to create dataset: {"message":{"table":["Dataset default.default.Distribution%20of%20Payment%20Methods already exists"]}}
[2025-05-23T09:29:21.377+0000] {subprocess.py:93} INFO - 
[2025-05-23T09:29:21.378+0000] {subprocess.py:93} INFO - Status: 422
[2025-05-23T09:29:21.379+0000] {subprocess.py:93} INFO - ‚ùå Failed to create dataset: {"message":"Fatal error"}
[2025-05-23T09:29:21.379+0000] {subprocess.py:93} INFO - 
[2025-05-23T09:29:21.380+0000] {subprocess.py:93} INFO - Status: 500
[2025-05-23T09:29:21.380+0000] {subprocess.py:93} INFO - ‚ùå Failed to create dataset: {"message":"Fatal error"}
[2025-05-23T09:29:21.381+0000] {subprocess.py:93} INFO - 
[2025-05-23T09:29:21.381+0000] {subprocess.py:93} INFO - Status: 500
[2025-05-23T09:29:21.382+0000] {subprocess.py:93} INFO - ‚ùå Failed to create dataset: {"message":"Fatal error"}
[2025-05-23T09:29:21.382+0000] {subprocess.py:93} INFO - 
[2025-05-23T09:29:21.383+0000] {subprocess.py:93} INFO - Status: 500
[2025-05-23T09:29:21.384+0000] {subprocess.py:93} INFO - ‚ùå Failed to create dataset: {"message":"Fatal error"}
[2025-05-23T09:29:21.384+0000] {subprocess.py:93} INFO - 
[2025-05-23T09:29:21.385+0000] {subprocess.py:93} INFO - Status: 500
[2025-05-23T09:29:21.386+0000] {subprocess.py:93} INFO - ‚ùå Failed to create dataset: {"message":"Fatal error"}
[2025-05-23T09:29:21.386+0000] {subprocess.py:93} INFO - 
[2025-05-23T09:29:21.387+0000] {subprocess.py:93} INFO - Status: 500
[2025-05-23T09:30:02.765+0000] {subprocess.py:93} INFO - üîê Authenticating with Superset...
[2025-05-23T09:30:02.766+0000] {subprocess.py:93} INFO - ‚úÖ Authentication successful
[2025-05-23T09:30:02.767+0000] {subprocess.py:93} INFO - 
[2025-05-23T09:30:02.767+0000] {subprocess.py:93} INFO - üöÄ Starting dashboard creation process...
[2025-05-23T09:30:02.768+0000] {subprocess.py:93} INFO - üìä Charts to create: 6
[2025-05-23T09:30:02.768+0000] {subprocess.py:93} INFO - üèóÔ∏è Dashboard name: Transaction Analytics Dashboard
[2025-05-23T09:30:02.768+0000] {subprocess.py:93} INFO - ==================================================
[2025-05-23T09:30:02.769+0000] {subprocess.py:93} INFO - üìä Creating chart: Fraud Detection Overview
[2025-05-23T09:30:02.769+0000] {subprocess.py:93} INFO - ‚ùå Dataset 'Proportion of Fraudulent Transactions' not found
[2025-05-23T09:30:02.769+0000] {subprocess.py:93} INFO - üìä Creating chart: Number of Transactions by Month
[2025-05-23T09:30:02.770+0000] {subprocess.py:93} INFO - ‚ùå Dataset 'Number of Transactions by Month' not found
[2025-05-23T09:30:02.770+0000] {subprocess.py:93} INFO - üìä Creating chart: Average Transaction Amount by Age Group
[2025-05-23T09:30:02.770+0000] {subprocess.py:93} INFO - ‚ùå Failed to create chart 'Average Transaction Amount by Age Group': {"message":"Chart could not be created."}
[2025-05-23T09:30:02.771+0000] {subprocess.py:93} INFO - 
[2025-05-23T09:30:02.771+0000] {subprocess.py:93} INFO - üìä Creating chart: Distribution of Payment Methods
[2025-05-23T09:30:02.772+0000] {subprocess.py:93} INFO - ‚úÖ Chart 'Distribution of Payment Methods' created (ID: 1)
[2025-05-23T09:30:02.772+0000] {subprocess.py:93} INFO - üìä Creating chart: Transaction Volume by Device Type
[2025-05-23T09:30:02.772+0000] {subprocess.py:93} INFO - ‚úÖ Chart 'Transaction Volume by Device Type' created (ID: 4)
[2025-05-23T09:30:02.773+0000] {subprocess.py:93} INFO - üìä Creating chart: Revenue by Product Category
[2025-05-23T09:30:02.773+0000] {subprocess.py:93} INFO - ‚úÖ Chart 'Revenue by Product Category' created (ID: 7)
[2025-05-23T09:30:02.774+0000] {subprocess.py:93} INFO - 
[2025-05-23T09:30:02.774+0000] {subprocess.py:93} INFO - üìà Successfully created 3 out of 6 charts
[2025-05-23T09:30:02.876+0000] {subprocess.py:93} INFO - python: can't open file '/app/step4_create_dashbord.py': [Errno 2] No such file or directory
[2025-05-23T09:30:02.886+0000] {subprocess.py:97} INFO - Command exited with return code 2
[2025-05-23T09:30:02.899+0000] {taskinstance.py:1943} ERROR - Task failed with exception
Traceback (most recent call last):
  File "/home/airflow/.local/lib/python3.9/site-packages/airflow/operators/bash.py", line 210, in execute
    raise AirflowException(
airflow.exceptions.AirflowException: Bash command failed. The command returned a non-zero exit code 2.
[2025-05-23T09:30:02.903+0000] {taskinstance.py:1400} INFO - Marking task as FAILED. dag_id=fetch_transaction_data_and_upload_to_hdfs, task_id=run_superset_dashboard, execution_date=20250523T092140, start_date=20250523T092821, end_date=20250523T093002
[2025-05-23T09:30:02.918+0000] {standard_task_runner.py:104} ERROR - Failed to execute job 23 for task run_superset_dashboard (Bash command failed. The command returned a non-zero exit code 2.; 688)
[2025-05-23T09:30:02.962+0000] {local_task_job_runner.py:228} INFO - Task exited with return code 1
[2025-05-23T09:30:02.985+0000] {taskinstance.py:2784} INFO - 0 downstream tasks scheduled from follow-on schedule check
