[2025-05-24T11:53:06.969+0000] {taskinstance.py:1159} INFO - Dependencies all met for dep_context=non-requeueable deps ti=<TaskInstance: fetch_transaction_data_and_upload_to_hdfs.check_hdfs_and_train_model scheduled__2025-05-23T00:00:00+00:00 [queued]>
[2025-05-24T11:53:06.982+0000] {taskinstance.py:1159} INFO - Dependencies all met for dep_context=requeueable deps ti=<TaskInstance: fetch_transaction_data_and_upload_to_hdfs.check_hdfs_and_train_model scheduled__2025-05-23T00:00:00+00:00 [queued]>
[2025-05-24T11:53:06.983+0000] {taskinstance.py:1361} INFO - Starting attempt 1 of 2
[2025-05-24T11:53:07.007+0000] {taskinstance.py:1382} INFO - Executing <Task(PythonOperator): check_hdfs_and_train_model> on 2025-05-23 00:00:00+00:00
[2025-05-24T11:53:07.022+0000] {standard_task_runner.py:57} INFO - Started process 5578 to run task
[2025-05-24T11:53:07.030+0000] {standard_task_runner.py:84} INFO - Running: ['***', 'tasks', 'run', 'fetch_transaction_data_and_upload_to_hdfs', 'check_hdfs_and_train_model', 'scheduled__2025-05-23T00:00:00+00:00', '--job-id', '45', '--raw', '--subdir', 'DAGS_FOLDER/ETL.py', '--cfg-path', '/tmp/tmpgiv2k9bz']
[2025-05-24T11:53:07.035+0000] {standard_task_runner.py:85} INFO - Job 45: Subtask check_hdfs_and_train_model
[2025-05-24T11:53:07.208+0000] {task_command.py:415} INFO - Running <TaskInstance: fetch_transaction_data_and_upload_to_hdfs.check_hdfs_and_train_model scheduled__2025-05-23T00:00:00+00:00 [running]> on host 6c702459c558
[2025-05-24T11:53:08.677+0000] {taskinstance.py:1660} INFO - Exporting env vars: AIRFLOW_CTX_DAG_OWNER='***' AIRFLOW_CTX_DAG_ID='fetch_transaction_data_and_upload_to_hdfs' AIRFLOW_CTX_TASK_ID='check_hdfs_and_train_model' AIRFLOW_CTX_EXECUTION_DATE='2025-05-23T00:00:00+00:00' AIRFLOW_CTX_TRY_NUMBER='1' AIRFLOW_CTX_DAG_RUN_ID='scheduled__2025-05-23T00:00:00+00:00'
[2025-05-24T11:53:12.325+0000] {local_task_job_runner.py:115} ERROR - Received SIGTERM. Terminating subprocesses
[2025-05-24T11:53:12.331+0000] {process_utils.py:131} INFO - Sending 15 to group 5578. PIDs of all processes in the group: [5582, 5578]
[2025-05-24T11:53:12.334+0000] {process_utils.py:86} INFO - Sending the signal 15 to group 5578
[2025-05-24T11:53:12.336+0000] {taskinstance.py:1632} ERROR - Received SIGTERM. Terminating subprocesses.
[2025-05-24T11:53:12.355+0000] {process_utils.py:79} INFO - Process psutil.Process(pid=5582, status='terminated', started='11:53:07') (5582) terminated with exit code None
[2025-05-24T11:53:13.108+0000] {standard_task_runner.py:104} ERROR - Failed to execute job 45 for task check_hdfs_and_train_model ((psycopg2.OperationalError) connection to server at "postgres" (172.18.0.3), port 5432 failed: Connection refused
	Is the server running on that host and accepting TCP/IP connections?

(Background on this error at: https://sqlalche.me/e/14/e3q8); 5578)
[2025-05-24T11:53:13.645+0000] {process_utils.py:79} INFO - Process psutil.Process(pid=5578, status='terminated', exitcode=1, started='11:53:06') (5578) terminated with exit code 1
[2025-05-24T11:53:13.669+0000] {local_task_job_runner.py:228} INFO - Task exited with return code 143
[2025-05-24T11:53:13.722+0000] {taskinstance.py:2790} INFO - Skipping mini scheduling run due to exception: None
Traceback (most recent call last):
  File "/home/airflow/.local/lib/python3.9/site-packages/sqlalchemy/engine/base.py", line 3371, in _wrap_pool_connect
    return fn()
  File "/home/airflow/.local/lib/python3.9/site-packages/sqlalchemy/pool/base.py", line 327, in connect
    return _ConnectionFairy._checkout(self)
  File "/home/airflow/.local/lib/python3.9/site-packages/sqlalchemy/pool/base.py", line 894, in _checkout
    fairy = _ConnectionRecord.checkout(pool)
  File "/home/airflow/.local/lib/python3.9/site-packages/sqlalchemy/pool/base.py", line 493, in checkout
    rec = pool._do_get()
  File "/home/airflow/.local/lib/python3.9/site-packages/sqlalchemy/pool/impl.py", line 256, in _do_get
    return self._create_connection()
  File "/home/airflow/.local/lib/python3.9/site-packages/sqlalchemy/pool/base.py", line 273, in _create_connection
    return _ConnectionRecord(self)
  File "/home/airflow/.local/lib/python3.9/site-packages/sqlalchemy/pool/base.py", line 388, in __init__
    self.__connect()
  File "/home/airflow/.local/lib/python3.9/site-packages/sqlalchemy/pool/base.py", line 691, in __connect
    pool.logger.debug("Error on connect(): %s", e)
  File "/home/airflow/.local/lib/python3.9/site-packages/sqlalchemy/util/langhelpers.py", line 70, in __exit__
    compat.raise_(
  File "/home/airflow/.local/lib/python3.9/site-packages/sqlalchemy/util/compat.py", line 211, in raise_
    raise exception
  File "/home/airflow/.local/lib/python3.9/site-packages/sqlalchemy/pool/base.py", line 686, in __connect
    self.dbapi_connection = connection = pool._invoke_creator(self)
  File "/home/airflow/.local/lib/python3.9/site-packages/sqlalchemy/engine/create.py", line 574, in connect
    return dialect.connect(*cargs, **cparams)
  File "/home/airflow/.local/lib/python3.9/site-packages/sqlalchemy/engine/default.py", line 598, in connect
    return self.dbapi.connect(*cargs, **cparams)
  File "/home/airflow/.local/lib/python3.9/site-packages/psycopg2/__init__.py", line 122, in connect
    conn = _connect(dsn, connection_factory=connection_factory, **kwasync)
psycopg2.OperationalError: connection to server at "postgres" (172.18.0.3), port 5432 failed: Connection refused
	Is the server running on that host and accepting TCP/IP connections?


The above exception was the direct cause of the following exception:

Traceback (most recent call last):
  File "/home/airflow/.local/lib/python3.9/site-packages/airflow/models/taskinstance.py", line 2739, in schedule_downstream_tasks
    dag_run = with_row_locks(
  File "/home/airflow/.local/lib/python3.9/site-packages/sqlalchemy/orm/query.py", line 2870, in one
    return self._iter().one()
  File "/home/airflow/.local/lib/python3.9/site-packages/sqlalchemy/orm/query.py", line 2916, in _iter
    result = self.session.execute(
  File "/home/airflow/.local/lib/python3.9/site-packages/sqlalchemy/orm/session.py", line 1716, in execute
    conn = self._connection_for_bind(bind)
  File "/home/airflow/.local/lib/python3.9/site-packages/sqlalchemy/orm/session.py", line 1555, in _connection_for_bind
    return self._transaction._connection_for_bind(
  File "/home/airflow/.local/lib/python3.9/site-packages/sqlalchemy/orm/session.py", line 750, in _connection_for_bind
    conn = bind.connect()
  File "/home/airflow/.local/lib/python3.9/site-packages/sqlalchemy/future/engine.py", line 406, in connect
    return super(Engine, self).connect()
  File "/home/airflow/.local/lib/python3.9/site-packages/sqlalchemy/engine/base.py", line 3325, in connect
    return self._connection_cls(self, close_with_result=close_with_result)
  File "/home/airflow/.local/lib/python3.9/site-packages/sqlalchemy/engine/base.py", line 96, in __init__
    else engine.raw_connection()
  File "/home/airflow/.local/lib/python3.9/site-packages/sqlalchemy/engine/base.py", line 3404, in raw_connection
    return self._wrap_pool_connect(self.pool.connect, _connection)
  File "/home/airflow/.local/lib/python3.9/site-packages/sqlalchemy/engine/base.py", line 3374, in _wrap_pool_connect
    Connection._handle_dbapi_exception_noconnection(
  File "/home/airflow/.local/lib/python3.9/site-packages/sqlalchemy/engine/base.py", line 2208, in _handle_dbapi_exception_noconnection
    util.raise_(
  File "/home/airflow/.local/lib/python3.9/site-packages/sqlalchemy/util/compat.py", line 211, in raise_
    raise exception
  File "/home/airflow/.local/lib/python3.9/site-packages/sqlalchemy/engine/base.py", line 3371, in _wrap_pool_connect
    return fn()
  File "/home/airflow/.local/lib/python3.9/site-packages/sqlalchemy/pool/base.py", line 327, in connect
    return _ConnectionFairy._checkout(self)
  File "/home/airflow/.local/lib/python3.9/site-packages/sqlalchemy/pool/base.py", line 894, in _checkout
    fairy = _ConnectionRecord.checkout(pool)
  File "/home/airflow/.local/lib/python3.9/site-packages/sqlalchemy/pool/base.py", line 493, in checkout
    rec = pool._do_get()
  File "/home/airflow/.local/lib/python3.9/site-packages/sqlalchemy/pool/impl.py", line 256, in _do_get
    return self._create_connection()
  File "/home/airflow/.local/lib/python3.9/site-packages/sqlalchemy/pool/base.py", line 273, in _create_connection
    return _ConnectionRecord(self)
  File "/home/airflow/.local/lib/python3.9/site-packages/sqlalchemy/pool/base.py", line 388, in __init__
    self.__connect()
  File "/home/airflow/.local/lib/python3.9/site-packages/sqlalchemy/pool/base.py", line 691, in __connect
    pool.logger.debug("Error on connect(): %s", e)
  File "/home/airflow/.local/lib/python3.9/site-packages/sqlalchemy/util/langhelpers.py", line 70, in __exit__
    compat.raise_(
  File "/home/airflow/.local/lib/python3.9/site-packages/sqlalchemy/util/compat.py", line 211, in raise_
    raise exception
  File "/home/airflow/.local/lib/python3.9/site-packages/sqlalchemy/pool/base.py", line 686, in __connect
    self.dbapi_connection = connection = pool._invoke_creator(self)
  File "/home/airflow/.local/lib/python3.9/site-packages/sqlalchemy/engine/create.py", line 574, in connect
    return dialect.connect(*cargs, **cparams)
  File "/home/airflow/.local/lib/python3.9/site-packages/sqlalchemy/engine/default.py", line 598, in connect
    return self.dbapi.connect(*cargs, **cparams)
  File "/home/airflow/.local/lib/python3.9/site-packages/psycopg2/__init__.py", line 122, in connect
    conn = _connect(dsn, connection_factory=connection_factory, **kwasync)
sqlalchemy.exc.OperationalError: (psycopg2.OperationalError) connection to server at "postgres" (172.18.0.3), port 5432 failed: Connection refused
	Is the server running on that host and accepting TCP/IP connections?

(Background on this error at: https://sqlalche.me/e/14/e3q8)
[2025-05-24T11:53:16.704+0000] {job.py:219} ERROR - Job heartbeat got an exception
Traceback (most recent call last):
  File "/home/airflow/.local/lib/python3.9/site-packages/sqlalchemy/engine/base.py", line 3371, in _wrap_pool_connect
    return fn()
  File "/home/airflow/.local/lib/python3.9/site-packages/sqlalchemy/pool/base.py", line 327, in connect
    return _ConnectionFairy._checkout(self)
  File "/home/airflow/.local/lib/python3.9/site-packages/sqlalchemy/pool/base.py", line 894, in _checkout
    fairy = _ConnectionRecord.checkout(pool)
  File "/home/airflow/.local/lib/python3.9/site-packages/sqlalchemy/pool/base.py", line 493, in checkout
    rec = pool._do_get()
  File "/home/airflow/.local/lib/python3.9/site-packages/sqlalchemy/pool/impl.py", line 256, in _do_get
    return self._create_connection()
  File "/home/airflow/.local/lib/python3.9/site-packages/sqlalchemy/pool/base.py", line 273, in _create_connection
    return _ConnectionRecord(self)
  File "/home/airflow/.local/lib/python3.9/site-packages/sqlalchemy/pool/base.py", line 388, in __init__
    self.__connect()
  File "/home/airflow/.local/lib/python3.9/site-packages/sqlalchemy/pool/base.py", line 691, in __connect
    pool.logger.debug("Error on connect(): %s", e)
  File "/home/airflow/.local/lib/python3.9/site-packages/sqlalchemy/util/langhelpers.py", line 70, in __exit__
    compat.raise_(
  File "/home/airflow/.local/lib/python3.9/site-packages/sqlalchemy/util/compat.py", line 211, in raise_
    raise exception
  File "/home/airflow/.local/lib/python3.9/site-packages/sqlalchemy/pool/base.py", line 686, in __connect
    self.dbapi_connection = connection = pool._invoke_creator(self)
  File "/home/airflow/.local/lib/python3.9/site-packages/sqlalchemy/engine/create.py", line 574, in connect
    return dialect.connect(*cargs, **cparams)
  File "/home/airflow/.local/lib/python3.9/site-packages/sqlalchemy/engine/default.py", line 598, in connect
    return self.dbapi.connect(*cargs, **cparams)
  File "/home/airflow/.local/lib/python3.9/site-packages/psycopg2/__init__.py", line 122, in connect
    conn = _connect(dsn, connection_factory=connection_factory, **kwasync)
psycopg2.OperationalError: could not translate host name "postgres" to address: Name or service not known


The above exception was the direct cause of the following exception:

Traceback (most recent call last):
  File "/home/airflow/.local/lib/python3.9/site-packages/airflow/jobs/job.py", line 190, in heartbeat
    session.merge(self)
  File "/home/airflow/.local/lib/python3.9/site-packages/sqlalchemy/orm/session.py", line 3056, in merge
    return self._merge(
  File "/home/airflow/.local/lib/python3.9/site-packages/sqlalchemy/orm/session.py", line 3136, in _merge
    merged = self.get(
  File "/home/airflow/.local/lib/python3.9/site-packages/sqlalchemy/orm/session.py", line 2853, in get
    return self._get_impl(
  File "/home/airflow/.local/lib/python3.9/site-packages/sqlalchemy/orm/session.py", line 2975, in _get_impl
    return db_load_fn(
  File "/home/airflow/.local/lib/python3.9/site-packages/sqlalchemy/orm/loading.py", line 530, in load_on_pk_identity
    session.execute(
  File "/home/airflow/.local/lib/python3.9/site-packages/sqlalchemy/orm/session.py", line 1716, in execute
    conn = self._connection_for_bind(bind)
  File "/home/airflow/.local/lib/python3.9/site-packages/sqlalchemy/orm/session.py", line 1555, in _connection_for_bind
    return self._transaction._connection_for_bind(
  File "/home/airflow/.local/lib/python3.9/site-packages/sqlalchemy/orm/session.py", line 750, in _connection_for_bind
    conn = bind.connect()
  File "/home/airflow/.local/lib/python3.9/site-packages/sqlalchemy/future/engine.py", line 406, in connect
    return super(Engine, self).connect()
  File "/home/airflow/.local/lib/python3.9/site-packages/sqlalchemy/engine/base.py", line 3325, in connect
    return self._connection_cls(self, close_with_result=close_with_result)
  File "/home/airflow/.local/lib/python3.9/site-packages/sqlalchemy/engine/base.py", line 96, in __init__
    else engine.raw_connection()
  File "/home/airflow/.local/lib/python3.9/site-packages/sqlalchemy/engine/base.py", line 3404, in raw_connection
    return self._wrap_pool_connect(self.pool.connect, _connection)
  File "/home/airflow/.local/lib/python3.9/site-packages/sqlalchemy/engine/base.py", line 3374, in _wrap_pool_connect
    Connection._handle_dbapi_exception_noconnection(
  File "/home/airflow/.local/lib/python3.9/site-packages/sqlalchemy/engine/base.py", line 2208, in _handle_dbapi_exception_noconnection
    util.raise_(
  File "/home/airflow/.local/lib/python3.9/site-packages/sqlalchemy/util/compat.py", line 211, in raise_
    raise exception
  File "/home/airflow/.local/lib/python3.9/site-packages/sqlalchemy/engine/base.py", line 3371, in _wrap_pool_connect
    return fn()
  File "/home/airflow/.local/lib/python3.9/site-packages/sqlalchemy/pool/base.py", line 327, in connect
    return _ConnectionFairy._checkout(self)
  File "/home/airflow/.local/lib/python3.9/site-packages/sqlalchemy/pool/base.py", line 894, in _checkout
    fairy = _ConnectionRecord.checkout(pool)
  File "/home/airflow/.local/lib/python3.9/site-packages/sqlalchemy/pool/base.py", line 493, in checkout
    rec = pool._do_get()
  File "/home/airflow/.local/lib/python3.9/site-packages/sqlalchemy/pool/impl.py", line 256, in _do_get
    return self._create_connection()
  File "/home/airflow/.local/lib/python3.9/site-packages/sqlalchemy/pool/base.py", line 273, in _create_connection
    return _ConnectionRecord(self)
  File "/home/airflow/.local/lib/python3.9/site-packages/sqlalchemy/pool/base.py", line 388, in __init__
    self.__connect()
  File "/home/airflow/.local/lib/python3.9/site-packages/sqlalchemy/pool/base.py", line 691, in __connect
    pool.logger.debug("Error on connect(): %s", e)
  File "/home/airflow/.local/lib/python3.9/site-packages/sqlalchemy/util/langhelpers.py", line 70, in __exit__
    compat.raise_(
  File "/home/airflow/.local/lib/python3.9/site-packages/sqlalchemy/util/compat.py", line 211, in raise_
    raise exception
  File "/home/airflow/.local/lib/python3.9/site-packages/sqlalchemy/pool/base.py", line 686, in __connect
    self.dbapi_connection = connection = pool._invoke_creator(self)
  File "/home/airflow/.local/lib/python3.9/site-packages/sqlalchemy/engine/create.py", line 574, in connect
    return dialect.connect(*cargs, **cparams)
  File "/home/airflow/.local/lib/python3.9/site-packages/sqlalchemy/engine/default.py", line 598, in connect
    return self.dbapi.connect(*cargs, **cparams)
  File "/home/airflow/.local/lib/python3.9/site-packages/psycopg2/__init__.py", line 122, in connect
    conn = _connect(dsn, connection_factory=connection_factory, **kwasync)
sqlalchemy.exc.OperationalError: (psycopg2.OperationalError) could not translate host name "postgres" to address: Name or service not known

(Background on this error at: https://sqlalche.me/e/14/e3q8)
[2025-05-24T12:23:08.861+0000] {taskinstance.py:1159} INFO - Dependencies all met for dep_context=non-requeueable deps ti=<TaskInstance: fetch_transaction_data_and_upload_to_hdfs.check_hdfs_and_train_model scheduled__2025-05-23T00:00:00+00:00 [queued]>
[2025-05-24T12:23:08.881+0000] {taskinstance.py:1159} INFO - Dependencies all met for dep_context=requeueable deps ti=<TaskInstance: fetch_transaction_data_and_upload_to_hdfs.check_hdfs_and_train_model scheduled__2025-05-23T00:00:00+00:00 [queued]>
[2025-05-24T12:23:08.881+0000] {taskinstance.py:1361} INFO - Starting attempt 1 of 2
[2025-05-24T12:23:08.909+0000] {taskinstance.py:1382} INFO - Executing <Task(PythonOperator): check_hdfs_and_train_model> on 2025-05-23 00:00:00+00:00
[2025-05-24T12:23:08.922+0000] {standard_task_runner.py:57} INFO - Started process 282 to run task
[2025-05-24T12:23:08.929+0000] {standard_task_runner.py:84} INFO - Running: ['***', 'tasks', 'run', 'fetch_transaction_data_and_upload_to_hdfs', 'check_hdfs_and_train_model', 'scheduled__2025-05-23T00:00:00+00:00', '--job-id', '6', '--raw', '--subdir', 'DAGS_FOLDER/ETL.py', '--cfg-path', '/tmp/tmplej9oo3w']
[2025-05-24T12:23:08.937+0000] {standard_task_runner.py:85} INFO - Job 6: Subtask check_hdfs_and_train_model
[2025-05-24T12:23:09.041+0000] {task_command.py:415} INFO - Running <TaskInstance: fetch_transaction_data_and_upload_to_hdfs.check_hdfs_and_train_model scheduled__2025-05-23T00:00:00+00:00 [running]> on host 1190334ace1e
[2025-05-24T12:23:09.578+0000] {taskinstance.py:1660} INFO - Exporting env vars: AIRFLOW_CTX_DAG_OWNER='***' AIRFLOW_CTX_DAG_ID='fetch_transaction_data_and_upload_to_hdfs' AIRFLOW_CTX_TASK_ID='check_hdfs_and_train_model' AIRFLOW_CTX_EXECUTION_DATE='2025-05-23T00:00:00+00:00' AIRFLOW_CTX_TRY_NUMBER='1' AIRFLOW_CTX_DAG_RUN_ID='scheduled__2025-05-23T00:00:00+00:00'
[2025-05-24T12:23:16.641+0000] {logging_mixin.py:151} INFO - ✅ Model already exists at hdfs://namenode:9000/user/root/model/fraud_detection. Skipping training.
[2025-05-24T12:23:16.643+0000] {taskinstance.py:1542} INFO - Model already exists in HDFS.
[2025-05-24T12:23:16.674+0000] {taskinstance.py:1400} INFO - Marking task as SKIPPED. dag_id=fetch_transaction_data_and_upload_to_hdfs, task_id=check_hdfs_and_train_model, execution_date=20250523T000000, start_date=20250524T122308, end_date=20250524T122316
[2025-05-24T12:23:16.855+0000] {local_task_job_runner.py:228} INFO - Task exited with return code 0
[2025-05-24T12:23:16.914+0000] {taskinstance.py:2784} INFO - 0 downstream tasks scheduled from follow-on schedule check
[2025-05-24T13:29:18.846+0000] {taskinstance.py:1159} INFO - Dependencies all met for dep_context=non-requeueable deps ti=<TaskInstance: fetch_transaction_data_and_upload_to_hdfs.check_hdfs_and_train_model scheduled__2025-05-23T00:00:00+00:00 [queued]>
[2025-05-24T13:29:18.866+0000] {taskinstance.py:1159} INFO - Dependencies all met for dep_context=requeueable deps ti=<TaskInstance: fetch_transaction_data_and_upload_to_hdfs.check_hdfs_and_train_model scheduled__2025-05-23T00:00:00+00:00 [queued]>
[2025-05-24T13:29:18.867+0000] {taskinstance.py:1361} INFO - Starting attempt 1 of 2
[2025-05-24T13:29:18.891+0000] {taskinstance.py:1382} INFO - Executing <Task(PythonOperator): check_hdfs_and_train_model> on 2025-05-23 00:00:00+00:00
[2025-05-24T13:29:18.901+0000] {standard_task_runner.py:57} INFO - Started process 254 to run task
[2025-05-24T13:29:18.908+0000] {standard_task_runner.py:84} INFO - Running: ['***', 'tasks', 'run', 'fetch_transaction_data_and_upload_to_hdfs', 'check_hdfs_and_train_model', 'scheduled__2025-05-23T00:00:00+00:00', '--job-id', '7', '--raw', '--subdir', 'DAGS_FOLDER/ETL.py', '--cfg-path', '/tmp/tmpc63tn0uw']
[2025-05-24T13:29:18.913+0000] {standard_task_runner.py:85} INFO - Job 7: Subtask check_hdfs_and_train_model
[2025-05-24T13:29:18.997+0000] {task_command.py:415} INFO - Running <TaskInstance: fetch_transaction_data_and_upload_to_hdfs.check_hdfs_and_train_model scheduled__2025-05-23T00:00:00+00:00 [running]> on host 1be44660cb93
[2025-05-24T13:29:19.776+0000] {taskinstance.py:1660} INFO - Exporting env vars: AIRFLOW_CTX_DAG_OWNER='***' AIRFLOW_CTX_DAG_ID='fetch_transaction_data_and_upload_to_hdfs' AIRFLOW_CTX_TASK_ID='check_hdfs_and_train_model' AIRFLOW_CTX_EXECUTION_DATE='2025-05-23T00:00:00+00:00' AIRFLOW_CTX_TRY_NUMBER='1' AIRFLOW_CTX_DAG_RUN_ID='scheduled__2025-05-23T00:00:00+00:00'
[2025-05-24T13:29:31.830+0000] {logging_mixin.py:151} INFO - ✅ Model already exists at hdfs://namenode:9000/user/root/model/fraud_detection. Skipping training.
[2025-05-24T13:29:31.831+0000] {taskinstance.py:1542} INFO - Model already exists in HDFS.
[2025-05-24T13:29:31.851+0000] {taskinstance.py:1400} INFO - Marking task as SKIPPED. dag_id=fetch_transaction_data_and_upload_to_hdfs, task_id=check_hdfs_and_train_model, execution_date=20250523T000000, start_date=20250524T132918, end_date=20250524T132931
[2025-05-24T13:29:31.908+0000] {local_task_job_runner.py:228} INFO - Task exited with return code 0
[2025-05-24T13:29:31.931+0000] {taskinstance.py:2784} INFO - 0 downstream tasks scheduled from follow-on schedule check
[2025-05-24T20:30:59.393+0000] {taskinstance.py:1159} INFO - Dependencies all met for dep_context=non-requeueable deps ti=<TaskInstance: fetch_transaction_data_and_upload_to_hdfs.check_hdfs_and_train_model scheduled__2025-05-23T00:00:00+00:00 [queued]>
[2025-05-24T20:30:59.415+0000] {taskinstance.py:1159} INFO - Dependencies all met for dep_context=requeueable deps ti=<TaskInstance: fetch_transaction_data_and_upload_to_hdfs.check_hdfs_and_train_model scheduled__2025-05-23T00:00:00+00:00 [queued]>
[2025-05-24T20:30:59.416+0000] {taskinstance.py:1361} INFO - Starting attempt 1 of 2
[2025-05-24T20:30:59.453+0000] {taskinstance.py:1382} INFO - Executing <Task(PythonOperator): check_hdfs_and_train_model> on 2025-05-23 00:00:00+00:00
[2025-05-24T20:30:59.471+0000] {standard_task_runner.py:57} INFO - Started process 619 to run task
[2025-05-24T20:30:59.478+0000] {standard_task_runner.py:84} INFO - Running: ['***', 'tasks', 'run', 'fetch_transaction_data_and_upload_to_hdfs', 'check_hdfs_and_train_model', 'scheduled__2025-05-23T00:00:00+00:00', '--job-id', '10', '--raw', '--subdir', 'DAGS_FOLDER/ETL.py', '--cfg-path', '/tmp/tmpdhd91kxl']
[2025-05-24T20:30:59.485+0000] {standard_task_runner.py:85} INFO - Job 10: Subtask check_hdfs_and_train_model
[2025-05-24T20:30:59.610+0000] {task_command.py:415} INFO - Running <TaskInstance: fetch_transaction_data_and_upload_to_hdfs.check_hdfs_and_train_model scheduled__2025-05-23T00:00:00+00:00 [running]> on host b7cf5396f9f1
[2025-05-24T20:30:59.811+0000] {taskinstance.py:1660} INFO - Exporting env vars: AIRFLOW_CTX_DAG_OWNER='***' AIRFLOW_CTX_DAG_ID='fetch_transaction_data_and_upload_to_hdfs' AIRFLOW_CTX_TASK_ID='check_hdfs_and_train_model' AIRFLOW_CTX_EXECUTION_DATE='2025-05-23T00:00:00+00:00' AIRFLOW_CTX_TRY_NUMBER='1' AIRFLOW_CTX_DAG_RUN_ID='scheduled__2025-05-23T00:00:00+00:00'
[2025-05-24T20:31:08.193+0000] {logging_mixin.py:151} INFO - ✅ Model already exists at hdfs://namenode:9000/user/root/model/fraud_detection. Skipping training.
[2025-05-24T20:31:08.199+0000] {taskinstance.py:1542} INFO - Model already exists in HDFS.
[2025-05-24T20:31:08.256+0000] {taskinstance.py:1400} INFO - Marking task as SKIPPED. dag_id=fetch_transaction_data_and_upload_to_hdfs, task_id=check_hdfs_and_train_model, execution_date=20250523T000000, start_date=20250524T203059, end_date=20250524T203108
[2025-05-24T20:31:08.347+0000] {local_task_job_runner.py:228} INFO - Task exited with return code 0
[2025-05-24T20:31:08.384+0000] {taskinstance.py:2784} INFO - 0 downstream tasks scheduled from follow-on schedule check
[2025-05-24T21:56:30.146+0000] {taskinstance.py:1159} INFO - Dependencies all met for dep_context=non-requeueable deps ti=<TaskInstance: fetch_transaction_data_and_upload_to_hdfs.check_hdfs_and_train_model scheduled__2025-05-23T00:00:00+00:00 [queued]>
[2025-05-24T21:56:30.163+0000] {taskinstance.py:1159} INFO - Dependencies all met for dep_context=requeueable deps ti=<TaskInstance: fetch_transaction_data_and_upload_to_hdfs.check_hdfs_and_train_model scheduled__2025-05-23T00:00:00+00:00 [queued]>
[2025-05-24T21:56:30.164+0000] {taskinstance.py:1361} INFO - Starting attempt 1 of 2
[2025-05-24T21:56:30.183+0000] {taskinstance.py:1382} INFO - Executing <Task(PythonOperator): check_hdfs_and_train_model> on 2025-05-23 00:00:00+00:00
[2025-05-24T21:56:30.200+0000] {standard_task_runner.py:57} INFO - Started process 270 to run task
[2025-05-24T21:56:30.204+0000] {standard_task_runner.py:84} INFO - Running: ['***', 'tasks', 'run', 'fetch_transaction_data_and_upload_to_hdfs', 'check_hdfs_and_train_model', 'scheduled__2025-05-23T00:00:00+00:00', '--job-id', '8', '--raw', '--subdir', 'DAGS_FOLDER/ETL.py', '--cfg-path', '/tmp/tmpqb1egp8z']
[2025-05-24T21:56:30.208+0000] {standard_task_runner.py:85} INFO - Job 8: Subtask check_hdfs_and_train_model
[2025-05-24T21:56:30.294+0000] {task_command.py:415} INFO - Running <TaskInstance: fetch_transaction_data_and_upload_to_hdfs.check_hdfs_and_train_model scheduled__2025-05-23T00:00:00+00:00 [running]> on host 65b298c9af88
[2025-05-24T21:56:30.463+0000] {taskinstance.py:1660} INFO - Exporting env vars: AIRFLOW_CTX_DAG_OWNER='***' AIRFLOW_CTX_DAG_ID='fetch_transaction_data_and_upload_to_hdfs' AIRFLOW_CTX_TASK_ID='check_hdfs_and_train_model' AIRFLOW_CTX_EXECUTION_DATE='2025-05-23T00:00:00+00:00' AIRFLOW_CTX_TRY_NUMBER='1' AIRFLOW_CTX_DAG_RUN_ID='scheduled__2025-05-23T00:00:00+00:00'
[2025-05-24T21:56:33.989+0000] {logging_mixin.py:151} INFO - ✅ Model already exists at hdfs://namenode:9000/user/root/model/fraud_detection. Skipping training.
[2025-05-24T21:56:33.990+0000] {taskinstance.py:1542} INFO - Model already exists in HDFS.
[2025-05-24T21:56:34.008+0000] {taskinstance.py:1400} INFO - Marking task as SKIPPED. dag_id=fetch_transaction_data_and_upload_to_hdfs, task_id=check_hdfs_and_train_model, execution_date=20250523T000000, start_date=20250524T215630, end_date=20250524T215634
[2025-05-24T21:56:34.088+0000] {local_task_job_runner.py:228} INFO - Task exited with return code 0
[2025-05-24T21:56:34.116+0000] {taskinstance.py:2784} INFO - 0 downstream tasks scheduled from follow-on schedule check
