[2025-05-09T19:22:09.722+0000] {taskinstance.py:1159} INFO - Dependencies all met for dep_context=non-requeueable deps ti=<TaskInstance: fetch_transaction_data_and_upload_to_hdfs.run_hive_command manual__2025-05-09T19:16:09.420603+00:00 [queued]>
[2025-05-09T19:22:09.733+0000] {taskinstance.py:1159} INFO - Dependencies all met for dep_context=requeueable deps ti=<TaskInstance: fetch_transaction_data_and_upload_to_hdfs.run_hive_command manual__2025-05-09T19:16:09.420603+00:00 [queued]>
[2025-05-09T19:22:09.734+0000] {taskinstance.py:1361} INFO - Starting attempt 2 of 2
[2025-05-09T19:22:09.762+0000] {taskinstance.py:1382} INFO - Executing <Task(PythonOperator): run_hive_command> on 2025-05-09 19:16:09.420603+00:00
[2025-05-09T19:22:09.771+0000] {standard_task_runner.py:57} INFO - Started process 7886 to run task
[2025-05-09T19:22:09.777+0000] {standard_task_runner.py:84} INFO - Running: ['***', 'tasks', 'run', 'fetch_transaction_data_and_upload_to_hdfs', 'run_hive_command', 'manual__2025-05-09T19:16:09.420603+00:00', '--job-id', '139', '--raw', '--subdir', 'DAGS_FOLDER/ingestion.py', '--cfg-path', '/tmp/tmp5nxrta6w']
[2025-05-09T19:22:09.781+0000] {standard_task_runner.py:85} INFO - Job 139: Subtask run_hive_command
[2025-05-09T19:22:09.846+0000] {task_command.py:415} INFO - Running <TaskInstance: fetch_transaction_data_and_upload_to_hdfs.run_hive_command manual__2025-05-09T19:16:09.420603+00:00 [running]> on host d4afc872a8aa
[2025-05-09T19:22:09.970+0000] {taskinstance.py:1660} INFO - Exporting env vars: AIRFLOW_CTX_DAG_OWNER='***' AIRFLOW_CTX_DAG_ID='fetch_transaction_data_and_upload_to_hdfs' AIRFLOW_CTX_TASK_ID='run_hive_command' AIRFLOW_CTX_EXECUTION_DATE='2025-05-09T19:16:09.420603+00:00' AIRFLOW_CTX_TRY_NUMBER='2' AIRFLOW_CTX_DAG_RUN_ID='manual__2025-05-09T19:16:09.420603+00:00'
[2025-05-09T19:22:12.861+0000] {taskinstance.py:1943} ERROR - Task failed with exception
Traceback (most recent call last):
  File "/opt/airflow/dags/ingestion.py", line 230, in run_hive_setup_or_query
    conn = psycopg2.connect(
  File "/home/airflow/.local/lib/python3.9/site-packages/psycopg2/__init__.py", line 122, in connect
    conn = _connect(dsn, connection_factory=connection_factory, **kwasync)
psycopg2.OperationalError: could not translate host name "stimming_processing-postgres-1" to address: Name or service not known


During handling of the above exception, another exception occurred:

Traceback (most recent call last):
  File "/home/airflow/.local/lib/python3.9/site-packages/airflow/operators/python.py", line 192, in execute
    return_value = self.execute_callable()
  File "/home/airflow/.local/lib/python3.9/site-packages/airflow/operators/python.py", line 209, in execute_callable
    return self.python_callable(*self.op_args, **self.op_kwargs)
  File "/opt/airflow/dags/ingestion.py", line 292, in run_hive_setup_or_query
    raise Exception(f"Error during Hive metastore setup: {str(e)}")
Exception: Error during Hive metastore setup: could not translate host name "stimming_processing-postgres-1" to address: Name or service not known

[2025-05-09T19:22:12.901+0000] {taskinstance.py:1400} INFO - Marking task as FAILED. dag_id=fetch_transaction_data_and_upload_to_hdfs, task_id=run_hive_command, execution_date=20250509T191609, start_date=20250509T192209, end_date=20250509T192212
[2025-05-09T19:22:12.927+0000] {standard_task_runner.py:104} ERROR - Failed to execute job 139 for task run_hive_command (Error during Hive metastore setup: could not translate host name "stimming_processing-postgres-1" to address: Name or service not known
; 7886)
[2025-05-09T19:22:12.964+0000] {local_task_job_runner.py:228} INFO - Task exited with return code 1
[2025-05-09T19:22:12.995+0000] {taskinstance.py:2784} INFO - 0 downstream tasks scheduled from follow-on schedule check
