[2025-05-24T12:24:23.125+0000] {taskinstance.py:1159} INFO - Dependencies all met for dep_context=non-requeueable deps ti=<TaskInstance: fetch_transaction_data_and_upload_to_hdfs.run_superset_dashboard scheduled__2025-05-23T00:00:00+00:00 [queued]>
[2025-05-24T12:24:23.138+0000] {taskinstance.py:1159} INFO - Dependencies all met for dep_context=requeueable deps ti=<TaskInstance: fetch_transaction_data_and_upload_to_hdfs.run_superset_dashboard scheduled__2025-05-23T00:00:00+00:00 [queued]>
[2025-05-24T12:24:23.139+0000] {taskinstance.py:1361} INFO - Starting attempt 1 of 2
[2025-05-24T12:24:23.154+0000] {taskinstance.py:1382} INFO - Executing <Task(BashOperator): run_superset_dashboard> on 2025-05-23 00:00:00+00:00
[2025-05-24T12:24:23.163+0000] {standard_task_runner.py:57} INFO - Started process 414 to run task
[2025-05-24T12:24:23.166+0000] {standard_task_runner.py:84} INFO - Running: ['***', 'tasks', 'run', 'fetch_transaction_data_and_upload_to_hdfs', 'run_superset_dashboard', 'scheduled__2025-05-23T00:00:00+00:00', '--job-id', '12', '--raw', '--subdir', 'DAGS_FOLDER/ETL.py', '--cfg-path', '/tmp/tmpdhwa2m7p']
[2025-05-24T12:24:23.169+0000] {standard_task_runner.py:85} INFO - Job 12: Subtask run_superset_dashboard
[2025-05-24T12:24:23.224+0000] {task_command.py:415} INFO - Running <TaskInstance: fetch_transaction_data_and_upload_to_hdfs.run_superset_dashboard scheduled__2025-05-23T00:00:00+00:00 [running]> on host 1190334ace1e
[2025-05-24T12:24:23.464+0000] {taskinstance.py:1660} INFO - Exporting env vars: AIRFLOW_CTX_DAG_OWNER='***' AIRFLOW_CTX_DAG_ID='fetch_transaction_data_and_upload_to_hdfs' AIRFLOW_CTX_TASK_ID='run_superset_dashboard' AIRFLOW_CTX_EXECUTION_DATE='2025-05-23T00:00:00+00:00' AIRFLOW_CTX_TRY_NUMBER='1' AIRFLOW_CTX_DAG_RUN_ID='scheduled__2025-05-23T00:00:00+00:00'
[2025-05-24T12:24:23.466+0000] {subprocess.py:63} INFO - Tmp dir root location: /tmp
[2025-05-24T12:24:23.468+0000] {subprocess.py:75} INFO - Running command: ['/bin/bash', '-c', 'docker exec superset python /app/dashboard/step1_connection_db.py && docker exec superset python /app/dashboard/step2_creation_of_datasets.py && docker exec superset python /app/dashboard/step3_create_charts.py && docker exec superset python /app/dashboard/step4_create_dashbord.py']
[2025-05-24T12:24:23.485+0000] {subprocess.py:86} INFO - Output:
[2025-05-24T12:24:25.527+0000] {subprocess.py:93} INFO - ✅ Login successful.
[2025-05-24T12:24:25.527+0000] {subprocess.py:93} INFO - Access Token: eyJhbGciOiJIUzI1NiIsInR5cCI6IkpXVCJ9.eyJmcmVzaCI6dHJ1ZSwiaWF0IjoxNzQ4MDg5NDY0LCJqdGkiOiJlOGIwMWQ2NC02OGUxLTRjNTUtOWQwMS0yMTc0NGFmNjFmZDciLCJ0eXBlIjoiYWNjZXNzIiwic3ViIjoxLCJuYmYiOjE3NDgwODk0NjQsImNzcmYiOiI5NjdjN2NjOC1kOTFlLTQ5YzAtOTRhZS03NTUzZDE5YzYyZTciLCJleHAiOjE3NDgwOTAzNjR9.C62iRvMJyMpXTVNei3gL9hi-id-TP7ARUlknJp9i5uI
[2025-05-24T12:24:25.528+0000] {subprocess.py:93} INFO - ✅ CSRF token received:
[2025-05-24T12:24:25.528+0000] {subprocess.py:93} INFO - IjQwNzNkZmI3NTNlOTkxMzQ3MzI3NWUxZjcyZTczMTVhNzhmMDYyNmUi.aDG6eA.hM_J7P7UugBMzJNAnxTFzh-CNTg
[2025-05-24T12:24:25.529+0000] {subprocess.py:93} INFO - Status: 500
[2025-05-24T12:24:25.529+0000] {subprocess.py:93} INFO - Response: {"errors": [{"message": "(builtins.NoneType) None\n[SQL: Could not connect to any of [('172.18.0.15', 10000)]]\n(Background on this error at: https://sqlalche.me/e/14/dbapi)", "error_type": "GENERIC_DB_ENGINE_ERROR", "level": "error", "extra": {"engine_name": "Apache Hive", "issue_codes": [{"code": 1002, "message": "Issue 1002 - The database returned an unexpected error."}]}}]}
[2025-05-24T12:24:26.227+0000] {subprocess.py:93} INFO - ✅ Logged in successfully
[2025-05-24T12:24:26.228+0000] {subprocess.py:93} INFO - ✅ CSRF token retrieved
[2025-05-24T12:24:26.229+0000] {subprocess.py:93} INFO - ❌ Failed to get Hive database ID: {"count":0,"description_columns":{},"ids":[],"label_columns":{"allow_ctas":"Allow Ctas","allow_cvas":"Allow Cvas","allow_dml":"Allow Dml","allow_file_upload":"Allow File Upload","allow_multi_catalog":"Allow Multi Catalog","allow_run_async":"Allow Run Async","allows_cost_estimate":"Allows Cost Estimate","allows_subquery":"Allows Subquery","allows_virtual_table_explore":"Allows Virtual Table Explore","backend":"Backend","changed_by.first_name":"Changed By First Name","changed_by.last_name":"Changed By Last Name","changed_on":"Changed On","changed_on_delta_humanized":"Changed On Delta Humanized","created_by.first_name":"Created By First Name","created_by.last_name":"Created By Last Name","database_name":"Database Name","disable_data_preview":"Disable Data Preview","disable_drill_to_detail":"Disable Drill To Detail","engine_information":"Engine Information","explore_database_id":"Explore Database Id","expose_in_sqllab":"Expose In Sqllab","extra":"Extra","force_ctas_schema":"Force Ctas Schema","id":"Id","uuid":"Uuid"},"list_columns":["allow_file_upload","allow_ctas","allow_cvas","allow_dml","allow_run_async","allows_cost_estimate","allows_subquery","allows_virtual_table_explore","backend","changed_on","changed_on_delta_humanized","changed_by.first_name","changed_by.last_name","created_by.first_name","created_by.last_name","database_name","explore_database_id","expose_in_sqllab","extra","force_ctas_schema","id","uuid","disable_data_preview","disable_drill_to_detail","allow_multi_catalog","engine_information"],"list_title":"List Database","order_columns":["allow_file_upload","allow_dml","allow_run_async","changed_on","changed_on_delta_humanized","created_by.first_name","database_name","expose_in_sqllab"],"result":[]}
[2025-05-24T12:24:26.230+0000] {subprocess.py:93} INFO - 
[2025-05-24T12:24:26.268+0000] {subprocess.py:97} INFO - Command exited with return code 1
[2025-05-24T12:24:26.284+0000] {taskinstance.py:1943} ERROR - Task failed with exception
Traceback (most recent call last):
  File "/home/airflow/.local/lib/python3.9/site-packages/airflow/operators/bash.py", line 210, in execute
    raise AirflowException(
airflow.exceptions.AirflowException: Bash command failed. The command returned a non-zero exit code 1.
[2025-05-24T12:24:26.292+0000] {taskinstance.py:1400} INFO - Marking task as UP_FOR_RETRY. dag_id=fetch_transaction_data_and_upload_to_hdfs, task_id=run_superset_dashboard, execution_date=20250523T000000, start_date=20250524T122423, end_date=20250524T122426
[2025-05-24T12:24:26.323+0000] {standard_task_runner.py:104} ERROR - Failed to execute job 12 for task run_superset_dashboard (Bash command failed. The command returned a non-zero exit code 1.; 414)
[2025-05-24T12:24:26.377+0000] {local_task_job_runner.py:228} INFO - Task exited with return code 1
[2025-05-24T12:24:26.406+0000] {taskinstance.py:2784} INFO - 0 downstream tasks scheduled from follow-on schedule check
[2025-05-24T13:30:30.169+0000] {taskinstance.py:1159} INFO - Dependencies all met for dep_context=non-requeueable deps ti=<TaskInstance: fetch_transaction_data_and_upload_to_hdfs.run_superset_dashboard scheduled__2025-05-23T00:00:00+00:00 [queued]>
[2025-05-24T13:30:30.185+0000] {taskinstance.py:1159} INFO - Dependencies all met for dep_context=requeueable deps ti=<TaskInstance: fetch_transaction_data_and_upload_to_hdfs.run_superset_dashboard scheduled__2025-05-23T00:00:00+00:00 [queued]>
[2025-05-24T13:30:30.186+0000] {taskinstance.py:1361} INFO - Starting attempt 1 of 2
[2025-05-24T13:30:30.206+0000] {taskinstance.py:1382} INFO - Executing <Task(BashOperator): run_superset_dashboard> on 2025-05-23 00:00:00+00:00
[2025-05-24T13:30:30.216+0000] {standard_task_runner.py:57} INFO - Started process 381 to run task
[2025-05-24T13:30:30.219+0000] {standard_task_runner.py:84} INFO - Running: ['***', 'tasks', 'run', 'fetch_transaction_data_and_upload_to_hdfs', 'run_superset_dashboard', 'scheduled__2025-05-23T00:00:00+00:00', '--job-id', '12', '--raw', '--subdir', 'DAGS_FOLDER/ETL.py', '--cfg-path', '/tmp/tmpm2tb9oyn']
[2025-05-24T13:30:30.223+0000] {standard_task_runner.py:85} INFO - Job 12: Subtask run_superset_dashboard
[2025-05-24T13:30:30.286+0000] {task_command.py:415} INFO - Running <TaskInstance: fetch_transaction_data_and_upload_to_hdfs.run_superset_dashboard scheduled__2025-05-23T00:00:00+00:00 [running]> on host 1be44660cb93
[2025-05-24T13:30:30.538+0000] {taskinstance.py:1660} INFO - Exporting env vars: AIRFLOW_CTX_DAG_OWNER='***' AIRFLOW_CTX_DAG_ID='fetch_transaction_data_and_upload_to_hdfs' AIRFLOW_CTX_TASK_ID='run_superset_dashboard' AIRFLOW_CTX_EXECUTION_DATE='2025-05-23T00:00:00+00:00' AIRFLOW_CTX_TRY_NUMBER='1' AIRFLOW_CTX_DAG_RUN_ID='scheduled__2025-05-23T00:00:00+00:00'
[2025-05-24T13:30:30.540+0000] {subprocess.py:63} INFO - Tmp dir root location: /tmp
[2025-05-24T13:30:30.542+0000] {subprocess.py:75} INFO - Running command: ['/bin/bash', '-c', 'docker exec superset python /app/dashboard/step1_connection_db.py && docker exec superset python /app/dashboard/step2_creation_of_datasets.py && docker exec superset python /app/dashboard/step3_create_charts.py && docker exec superset python /app/dashboard/step4_create_dashbord.py']
[2025-05-24T13:30:30.557+0000] {subprocess.py:86} INFO - Output:
[2025-05-24T13:30:31.277+0000] {subprocess.py:93} INFO - ✅ Login successful.
[2025-05-24T13:30:31.278+0000] {subprocess.py:93} INFO - Access Token: eyJhbGciOiJIUzI1NiIsInR5cCI6IkpXVCJ9.eyJmcmVzaCI6dHJ1ZSwiaWF0IjoxNzQ4MDkzNDMxLCJqdGkiOiI1OTRmOTZlMS00ZDVhLTQ0MDItYjgwNC05YmNmZjYwZjI4NzgiLCJ0eXBlIjoiYWNjZXNzIiwic3ViIjoxLCJuYmYiOjE3NDgwOTM0MzEsImNzcmYiOiI0OGE4NTcyZS1lZmZiLTRjZGYtODYxNC03NWUxZmNmMWI3ZjAiLCJleHAiOjE3NDgwOTQzMzF9.3X_MuAx8YXbe4ik8PheuzhMUHflI74aLa1QH5hsiGyo
[2025-05-24T13:30:31.278+0000] {subprocess.py:93} INFO - ✅ CSRF token received:
[2025-05-24T13:30:31.279+0000] {subprocess.py:93} INFO - IjhkZTNkZThkMDQ2YzQzYmRlYjI4ZmZhN2JkN2RiZmZhMmIwZTdlNTAi.aDHJ9w.crCLfdHWLaKvZ_a2xFO5PIFlF_g
[2025-05-24T13:30:31.279+0000] {subprocess.py:93} INFO - Status: 500
[2025-05-24T13:30:31.279+0000] {subprocess.py:93} INFO - Response: {"errors": [{"message": "(builtins.NoneType) None\n[SQL: Could not connect to any of [('172.18.0.12', 10000)]]\n(Background on this error at: https://sqlalche.me/e/14/dbapi)", "error_type": "GENERIC_DB_ENGINE_ERROR", "level": "error", "extra": {"engine_name": "Apache Hive", "issue_codes": [{"code": 1002, "message": "Issue 1002 - The database returned an unexpected error."}]}}]}
[2025-05-24T13:30:31.888+0000] {subprocess.py:93} INFO - ✅ Logged in successfully
[2025-05-24T13:30:31.891+0000] {subprocess.py:93} INFO - ✅ CSRF token retrieved
[2025-05-24T13:30:31.892+0000] {subprocess.py:93} INFO - ❌ Failed to get Hive database ID: {"count":0,"description_columns":{},"ids":[],"label_columns":{"allow_ctas":"Allow Ctas","allow_cvas":"Allow Cvas","allow_dml":"Allow Dml","allow_file_upload":"Allow File Upload","allow_multi_catalog":"Allow Multi Catalog","allow_run_async":"Allow Run Async","allows_cost_estimate":"Allows Cost Estimate","allows_subquery":"Allows Subquery","allows_virtual_table_explore":"Allows Virtual Table Explore","backend":"Backend","changed_by.first_name":"Changed By First Name","changed_by.last_name":"Changed By Last Name","changed_on":"Changed On","changed_on_delta_humanized":"Changed On Delta Humanized","created_by.first_name":"Created By First Name","created_by.last_name":"Created By Last Name","database_name":"Database Name","disable_data_preview":"Disable Data Preview","disable_drill_to_detail":"Disable Drill To Detail","engine_information":"Engine Information","explore_database_id":"Explore Database Id","expose_in_sqllab":"Expose In Sqllab","extra":"Extra","force_ctas_schema":"Force Ctas Schema","id":"Id","uuid":"Uuid"},"list_columns":["allow_file_upload","allow_ctas","allow_cvas","allow_dml","allow_run_async","allows_cost_estimate","allows_subquery","allows_virtual_table_explore","backend","changed_on","changed_on_delta_humanized","changed_by.first_name","changed_by.last_name","created_by.first_name","created_by.last_name","database_name","explore_database_id","expose_in_sqllab","extra","force_ctas_schema","id","uuid","disable_data_preview","disable_drill_to_detail","allow_multi_catalog","engine_information"],"list_title":"List Database","order_columns":["allow_file_upload","allow_dml","allow_run_async","changed_on","changed_on_delta_humanized","created_by.first_name","database_name","expose_in_sqllab"],"result":[]}
[2025-05-24T13:30:31.892+0000] {subprocess.py:93} INFO - 
[2025-05-24T13:30:31.929+0000] {subprocess.py:97} INFO - Command exited with return code 1
[2025-05-24T13:30:31.945+0000] {taskinstance.py:1943} ERROR - Task failed with exception
Traceback (most recent call last):
  File "/home/airflow/.local/lib/python3.9/site-packages/airflow/operators/bash.py", line 210, in execute
    raise AirflowException(
airflow.exceptions.AirflowException: Bash command failed. The command returned a non-zero exit code 1.
[2025-05-24T13:30:31.950+0000] {taskinstance.py:1400} INFO - Marking task as UP_FOR_RETRY. dag_id=fetch_transaction_data_and_upload_to_hdfs, task_id=run_superset_dashboard, execution_date=20250523T000000, start_date=20250524T133030, end_date=20250524T133031
[2025-05-24T13:30:31.969+0000] {standard_task_runner.py:104} ERROR - Failed to execute job 12 for task run_superset_dashboard (Bash command failed. The command returned a non-zero exit code 1.; 381)
[2025-05-24T13:30:32.011+0000] {local_task_job_runner.py:228} INFO - Task exited with return code 1
[2025-05-24T13:30:32.039+0000] {taskinstance.py:2784} INFO - 0 downstream tasks scheduled from follow-on schedule check
