[2025-05-23T10:12:03.114+0000] {taskinstance.py:1159} INFO - Dependencies all met for dep_context=non-requeueable deps ti=<TaskInstance: fetch_transaction_data_and_upload_to_hdfs.run_superset_dashboard manual__2025-05-23T10:04:14.799182+00:00 [queued]>
[2025-05-23T10:12:03.125+0000] {taskinstance.py:1159} INFO - Dependencies all met for dep_context=requeueable deps ti=<TaskInstance: fetch_transaction_data_and_upload_to_hdfs.run_superset_dashboard manual__2025-05-23T10:04:14.799182+00:00 [queued]>
[2025-05-23T10:12:03.126+0000] {taskinstance.py:1361} INFO - Starting attempt 2 of 2
[2025-05-23T10:12:03.141+0000] {taskinstance.py:1382} INFO - Executing <Task(BashOperator): run_superset_dashboard> on 2025-05-23 10:04:14.799182+00:00
[2025-05-23T10:12:03.148+0000] {standard_task_runner.py:57} INFO - Started process 1313 to run task
[2025-05-23T10:12:03.151+0000] {standard_task_runner.py:84} INFO - Running: ['***', 'tasks', 'run', 'fetch_transaction_data_and_upload_to_hdfs', 'run_superset_dashboard', 'manual__2025-05-23T10:04:14.799182+00:00', '--job-id', '34', '--raw', '--subdir', 'DAGS_FOLDER/ETL.py', '--cfg-path', '/tmp/tmpkw8rzp1e']
[2025-05-23T10:12:03.155+0000] {standard_task_runner.py:85} INFO - Job 34: Subtask run_superset_dashboard
[2025-05-23T10:12:03.207+0000] {task_command.py:415} INFO - Running <TaskInstance: fetch_transaction_data_and_upload_to_hdfs.run_superset_dashboard manual__2025-05-23T10:04:14.799182+00:00 [running]> on host 6c702459c558
[2025-05-23T10:12:03.464+0000] {taskinstance.py:1660} INFO - Exporting env vars: AIRFLOW_CTX_DAG_OWNER='***' AIRFLOW_CTX_DAG_ID='fetch_transaction_data_and_upload_to_hdfs' AIRFLOW_CTX_TASK_ID='run_superset_dashboard' AIRFLOW_CTX_EXECUTION_DATE='2025-05-23T10:04:14.799182+00:00' AIRFLOW_CTX_TRY_NUMBER='2' AIRFLOW_CTX_DAG_RUN_ID='manual__2025-05-23T10:04:14.799182+00:00'
[2025-05-23T10:12:03.466+0000] {subprocess.py:63} INFO - Tmp dir root location: /tmp
[2025-05-23T10:12:03.467+0000] {subprocess.py:75} INFO - Running command: ['/bin/bash', '-c', 'docker exec superset python /app/dashboard/step1_connection_db.py && docker exec superset python /app/dashboard/step2_creation_of_datasets.py && docker exec superset python /app/dashboard/step3_create_charts.py && docker exec superset python /app/dashboard/step4_create_dashboard.py']
[2025-05-23T10:12:03.482+0000] {subprocess.py:86} INFO - Output:
[2025-05-23T10:12:03.910+0000] {subprocess.py:93} INFO - ‚úÖ Login successful.
[2025-05-23T10:12:03.912+0000] {subprocess.py:93} INFO - Access Token: eyJhbGciOiJIUzI1NiIsInR5cCI6IkpXVCJ9.eyJmcmVzaCI6dHJ1ZSwiaWF0IjoxNzQ3OTk1MTIzLCJqdGkiOiI1ZWIyYTE0Ny1iZjA1LTQ1ZWQtOWRiMS0wMDUyYzgwODMyMmUiLCJ0eXBlIjoiYWNjZXNzIiwic3ViIjoxLCJuYmYiOjE3NDc5OTUxMjMsImNzcmYiOiJlOWY4NDc0NC1iNWI0LTRjNDctOWE2ZC0xYTk0OGI1ZTAzM2UiLCJleHAiOjE3NDc5OTYwMjN9.Nq89M91-y71DI8kibFnKzkAwnevCP0lgclY3gVLQYts
[2025-05-23T10:12:03.912+0000] {subprocess.py:93} INFO - ‚úÖ CSRF token received:
[2025-05-23T10:12:03.913+0000] {subprocess.py:93} INFO - ImEyMTA4NDgzYzFkMTRhMDJiMzc3NDIxMmIyN2E4MGJlYjU4ZmVjYmUi.aDBJ8w.SWlOJ_dsLhD7_LaHj8Fz5TZg54Q
[2025-05-23T10:12:03.913+0000] {subprocess.py:93} INFO - Status: 422
[2025-05-23T10:12:03.914+0000] {subprocess.py:93} INFO - Response: {"message":{"database_name":"A database with the same name already exists."}}
[2025-05-23T10:12:03.914+0000] {subprocess.py:93} INFO - 
[2025-05-23T10:12:04.493+0000] {subprocess.py:93} INFO - ‚úÖ Logged in successfully
[2025-05-23T10:12:04.494+0000] {subprocess.py:93} INFO - ‚úÖ CSRF token retrieved
[2025-05-23T10:12:04.495+0000] {subprocess.py:93} INFO - ‚úÖ Hive Warehouse database ID: 1
[2025-05-23T10:12:04.496+0000] {subprocess.py:93} INFO - ‚ùå Failed to create dataset: {"message":{"table":["Dataset default.default.Distribution%20of%20Payment%20Methods already exists"]}}
[2025-05-23T10:12:04.498+0000] {subprocess.py:93} INFO - 
[2025-05-23T10:12:04.499+0000] {subprocess.py:93} INFO - Status: 422
[2025-05-23T10:12:04.499+0000] {subprocess.py:93} INFO - ‚ùå Failed to create dataset: {"message":{"table":["Dataset default.default.Transaction%20Volume%20by%20Device%20Type already exists"]}}
[2025-05-23T10:12:04.500+0000] {subprocess.py:93} INFO - 
[2025-05-23T10:12:04.500+0000] {subprocess.py:93} INFO - Status: 422
[2025-05-23T10:12:04.501+0000] {subprocess.py:93} INFO - ‚ùå Failed to create dataset: {"message":{"table":["Dataset default.default.Average%20Transaction%20Amount%20by%20Customer%20Age%20Group already exists"]}}
[2025-05-23T10:12:04.501+0000] {subprocess.py:93} INFO - 
[2025-05-23T10:12:04.502+0000] {subprocess.py:93} INFO - Status: 422
[2025-05-23T10:12:04.502+0000] {subprocess.py:93} INFO - ‚ùå Failed to create dataset: {"message":{"table":["Dataset default.default.Number%20of%20Transactions%20by%20Month already exists"]}}
[2025-05-23T10:12:04.503+0000] {subprocess.py:93} INFO - 
[2025-05-23T10:12:04.503+0000] {subprocess.py:93} INFO - Status: 422
[2025-05-23T10:12:04.503+0000] {subprocess.py:93} INFO - ‚ùå Failed to create dataset: {"message":{"table":["Dataset default.default.Proportion%20of%20Fraudulent%20Transactions already exists"]}}
[2025-05-23T10:12:04.504+0000] {subprocess.py:93} INFO - 
[2025-05-23T10:12:04.504+0000] {subprocess.py:93} INFO - Status: 422
[2025-05-23T10:12:04.505+0000] {subprocess.py:93} INFO - ‚ùå Failed to create dataset: {"message":{"table":["Dataset default.default.Total%20Transaction%20Amount%20by%20Product%20Category already exists"]}}
[2025-05-23T10:12:04.505+0000] {subprocess.py:93} INFO - 
[2025-05-23T10:12:04.505+0000] {subprocess.py:93} INFO - Status: 422
[2025-05-23T10:12:11.468+0000] {subprocess.py:93} INFO - üîê Authenticating with Superset...
[2025-05-23T10:12:11.469+0000] {subprocess.py:93} INFO - ‚úÖ Authentication successful
[2025-05-23T10:12:11.470+0000] {subprocess.py:93} INFO - 
[2025-05-23T10:12:11.471+0000] {subprocess.py:93} INFO - üöÄ Starting dashboard creation process...
[2025-05-23T10:12:11.472+0000] {subprocess.py:93} INFO - üìä Charts to create: 6
[2025-05-23T10:12:11.473+0000] {subprocess.py:93} INFO - üèóÔ∏è Dashboard name: Transaction Analytics Dashboard
[2025-05-23T10:12:11.473+0000] {subprocess.py:93} INFO - ==================================================
[2025-05-23T10:12:11.473+0000] {subprocess.py:93} INFO - üìä Creating chart: Fraud Detection Overview
[2025-05-23T10:12:11.474+0000] {subprocess.py:93} INFO - ‚úÖ Chart 'Fraud Detection Overview' created (ID: 14)
[2025-05-23T10:12:11.474+0000] {subprocess.py:93} INFO - üìä Creating chart: Number of Transactions by Month
[2025-05-23T10:12:11.474+0000] {subprocess.py:93} INFO - ‚úÖ Chart 'Number of Transactions by Month' created (ID: 15)
[2025-05-23T10:12:11.475+0000] {subprocess.py:93} INFO - üìä Creating chart: Average Transaction Amount by Age Group
[2025-05-23T10:12:11.475+0000] {subprocess.py:93} INFO - ‚úÖ Chart 'Average Transaction Amount by Age Group' created (ID: 16)
[2025-05-23T10:12:11.475+0000] {subprocess.py:93} INFO - üìä Creating chart: Distribution of Payment Methods
[2025-05-23T10:12:11.475+0000] {subprocess.py:93} INFO - ‚úÖ Chart 'Distribution of Payment Methods' created (ID: 17)
[2025-05-23T10:12:11.475+0000] {subprocess.py:93} INFO - üìä Creating chart: Transaction Volume by Device Type
[2025-05-23T10:12:11.476+0000] {subprocess.py:93} INFO - ‚úÖ Chart 'Transaction Volume by Device Type' created (ID: 18)
[2025-05-23T10:12:11.476+0000] {subprocess.py:93} INFO - üìä Creating chart: Revenue by Product Category
[2025-05-23T10:12:11.476+0000] {subprocess.py:93} INFO - ‚úÖ Chart 'Revenue by Product Category' created (ID: 19)
[2025-05-23T10:12:11.476+0000] {subprocess.py:93} INFO - 
[2025-05-23T10:12:11.477+0000] {subprocess.py:93} INFO - üìà Successfully created 6 out of 6 charts
[2025-05-23T10:12:11.564+0000] {subprocess.py:93} INFO - python: can't open file '/app/dashboard/step4_create_dashboard.py': [Errno 2] No such file or directory
[2025-05-23T10:12:11.574+0000] {subprocess.py:97} INFO - Command exited with return code 2
[2025-05-23T10:12:11.583+0000] {taskinstance.py:1943} ERROR - Task failed with exception
Traceback (most recent call last):
  File "/home/airflow/.local/lib/python3.9/site-packages/airflow/operators/bash.py", line 210, in execute
    raise AirflowException(
airflow.exceptions.AirflowException: Bash command failed. The command returned a non-zero exit code 2.
[2025-05-23T10:12:11.587+0000] {taskinstance.py:1400} INFO - Marking task as FAILED. dag_id=fetch_transaction_data_and_upload_to_hdfs, task_id=run_superset_dashboard, execution_date=20250523T100414, start_date=20250523T101203, end_date=20250523T101211
[2025-05-23T10:12:11.601+0000] {standard_task_runner.py:104} ERROR - Failed to execute job 34 for task run_superset_dashboard (Bash command failed. The command returned a non-zero exit code 2.; 1313)
[2025-05-23T10:12:11.641+0000] {local_task_job_runner.py:228} INFO - Task exited with return code 1
[2025-05-23T10:12:11.663+0000] {taskinstance.py:2784} INFO - 0 downstream tasks scheduled from follow-on schedule check
