[2025-04-05T18:00:57.035+0000] {taskinstance.py:1159} INFO - Dependencies all met for dep_context=non-requeueable deps ti=<TaskInstance: fetch_transaction_data_and_upload_to_hdfs.upload_to_hdfs scheduled__2025-04-04T00:00:00+00:00 [queued]>
[2025-04-05T18:00:57.046+0000] {taskinstance.py:1159} INFO - Dependencies all met for dep_context=requeueable deps ti=<TaskInstance: fetch_transaction_data_and_upload_to_hdfs.upload_to_hdfs scheduled__2025-04-04T00:00:00+00:00 [queued]>
[2025-04-05T18:00:57.046+0000] {taskinstance.py:1361} INFO - Starting attempt 1 of 2
[2025-04-05T18:00:57.061+0000] {taskinstance.py:1382} INFO - Executing <Task(PythonOperator): upload_to_hdfs> on 2025-04-04 00:00:00+00:00
[2025-04-05T18:00:57.066+0000] {standard_task_runner.py:57} INFO - Started process 179 to run task
[2025-04-05T18:00:57.069+0000] {standard_task_runner.py:84} INFO - Running: ['***', 'tasks', 'run', 'fetch_transaction_data_and_upload_to_hdfs', 'upload_to_hdfs', 'scheduled__2025-04-04T00:00:00+00:00', '--job-id', '11', '--raw', '--subdir', 'DAGS_FOLDER/ingestion.py', '--cfg-path', '/tmp/tmplgqfd4ba']
[2025-04-05T18:00:57.072+0000] {standard_task_runner.py:85} INFO - Job 11: Subtask upload_to_hdfs
[2025-04-05T18:00:57.125+0000] {task_command.py:415} INFO - Running <TaskInstance: fetch_transaction_data_and_upload_to_hdfs.upload_to_hdfs scheduled__2025-04-04T00:00:00+00:00 [running]> on host 10fdfba06761
[2025-04-05T18:00:57.206+0000] {taskinstance.py:1660} INFO - Exporting env vars: AIRFLOW_CTX_DAG_OWNER='***' AIRFLOW_CTX_DAG_ID='fetch_transaction_data_and_upload_to_hdfs' AIRFLOW_CTX_TASK_ID='upload_to_hdfs' AIRFLOW_CTX_EXECUTION_DATE='2025-04-04T00:00:00+00:00' AIRFLOW_CTX_TRY_NUMBER='1' AIRFLOW_CTX_DAG_RUN_ID='scheduled__2025-04-04T00:00:00+00:00'
[2025-04-05T18:01:00.936+0000] {taskinstance.py:1943} ERROR - Task failed with exception
Traceback (most recent call last):
  File "/home/airflow/.local/lib/python3.9/site-packages/airflow/operators/python.py", line 192, in execute
    return_value = self.execute_callable()
  File "/home/airflow/.local/lib/python3.9/site-packages/airflow/operators/python.py", line 209, in execute_callable
    return self.python_callable(*self.op_args, **self.op_kwargs)
  File "/opt/airflow/dags/ingestion.py", line 50, in upload_to_hdfs
    raise Exception(f"Command failed: {bash_command}\nError: {result.stderr}")
Exception: Command failed: docker cp /tmp/transaction_data.csv namenode:/tmp/transaction_data.csv &&docker exec namenode bash -c "hdfs dfs -mkdir -p /user/root/transactions/YYYY=2025/MM=04/DD=04 && hdfs dfs -put -f /tmp/transaction_data.csv /user/root/transactions/YYYY=2025/MM=04/DD=04/transaction_data.csv"
Error: put: Cannot create file/user/root/transactions/YYYY=2025/MM=04/DD=04/transaction_data.csv._COPYING_. Name node is in safe mode.

[2025-04-05T18:01:00.951+0000] {taskinstance.py:1400} INFO - Marking task as UP_FOR_RETRY. dag_id=fetch_transaction_data_and_upload_to_hdfs, task_id=upload_to_hdfs, execution_date=20250404T000000, start_date=20250405T180057, end_date=20250405T180100
[2025-04-05T18:01:00.967+0000] {standard_task_runner.py:104} ERROR - Failed to execute job 11 for task upload_to_hdfs (Command failed: docker cp /tmp/transaction_data.csv namenode:/tmp/transaction_data.csv &&docker exec namenode bash -c "hdfs dfs -mkdir -p /user/root/transactions/YYYY=2025/MM=04/DD=04 && hdfs dfs -put -f /tmp/transaction_data.csv /user/root/transactions/YYYY=2025/MM=04/DD=04/transaction_data.csv"
Error: put: Cannot create file/user/root/transactions/YYYY=2025/MM=04/DD=04/transaction_data.csv._COPYING_. Name node is in safe mode.
; 179)
[2025-04-05T18:01:01.005+0000] {local_task_job_runner.py:228} INFO - Task exited with return code 1
[2025-04-05T18:01:01.026+0000] {taskinstance.py:2784} INFO - 0 downstream tasks scheduled from follow-on schedule check
